<?xml version="1.0" ?>
<!-- =================================================================================== -->
<!-- |    This document was autogenerated by xacro from quad_final_with_camera_quadrotor_drive.xacro | -->
<!-- |    EDITING THIS FILE BY HAND IS NOT RECOMMENDED                                 | -->
<!-- =================================================================================== -->
<robot name="generic_quad_sim" xmlns:xacro="http://www.ros.org/wiki/xacro">
   --&gt;

	
  <!-- Base Link -->
  <link name="base_link">
    <visual>
      <geometry>
        <box size="0.05 0.05 0.04"/>
      </geometry>
      <origin rpy="0.0 0.0 0.0" xyz="0.0 0.0 0.04"/>
      <material name="balck">
        <color rgba="0 0 0 1"/>
      </material>
    </visual>
    <collsion>
      <geometry>
        <box size="0.05 0.05 0.04"/>
        <origin rpy="0.0 0.0 0.0" xyz="0.0 0.0 0.03"/>
      </geometry>
    </collsion>
    <inertial>
      <mass value="0.3"/>
      <inertia ixx="0.000125" ixy="0" ixz="0" iyy="0.0001025" iyz="0" izz="0.000125"/>
    </inertial>
  </link>
  <gazebo reference="base_link">
    <material>Gazebo/Black</material>
    <pose>0 0 0.02 0 0 0</pose>
  </gazebo>
  <!-- Imu Link -->
  <link name="imu_link">
    <visual>
      <origin rpy="0 0 0" xyz="0.0 0.0 0.02"/>
      <geometry>
        <box size="0.02 0.02 0.02"/>
      </geometry>
    </visual>
    <collision>
      <origin rpy="0 0 0" xyz="0.0 0.0 0.02"/>
      <geometry>
        <box size="0.02 0.02 0.02"/>
      </geometry>
    </collision>
    <inertial>
      <mass value="0.001"/>
      <origin rpy="0 0 0" xyz="0 0 0"/>
      <inertia ixx="3.33333333333e-08" ixy="0.0" ixz="0.0" iyy="3.33333333333e-08" iyz="0.0" izz="6.66666666667e-05"/>
    </inertial>
  </link>
  <gazebo reference="imu_link">
    <gravity>true</gravity>
    <material>Gazebo/Black</material>
    <pose>0 0 0 0 0 0</pose>
    <sensor name="imu_sensor" type="imu">
      <always_on>1</always_on>
      <update_rate>1000</update_rate>
      <visualize>1</visualize>
      <topic>__default_topic__</topic>
      <plugin filename="libgazebo_ros_imu_sensor.so" name="imu_plugin">
        <topicName>imu_data</topicName>
        <bodyName>imu_link</bodyName>
        <updateRateHZ>10.0</updateRateHZ>
        <gaussianNoise>0.0</gaussianNoise>
        <xyzOffset>0 0 0</xyzOffset>
        <rpyOffset>0 0 0</rpyOffset>
      </plugin>
    </sensor>
  </gazebo>
  <!-- Imu Joint -->
  <joint name="base_link_to_imu_sensor" type="fixed">
    <axis xyz="0 0 1"/>
    <origin rpy="0 0 1" xyz="0.0 0.0 0.04"/>
    <parent link="base_link"/>
    <child link="imu_link"/>
  </joint>
  <!-- Camera Link -->
  <link name="bottom_camera_link">
    <visual>
      <geometry>
        <box size="0.005 0.005 0.008"/>
        <origin rpy="3.14149265359 0 0" xyz="0.0 0.0 0"/>
      </geometry>
      <material name="white">
        <color rgba="1 1 1 1"/>
      </material>
    </visual>
    <collision>
      <geometry>
        <box size="0.005 0.005 0.008"/>
        <origin rpy="3.14149265359 0 0" xyz="0.0 0.0 0"/>
      </geometry>
    </collision>
    <inertial>
      <mass value="0.03"/>
      <inertia ixx="1.25e-07" ixy="0" ixz="0" iyy="2.225e-07" iyz="0" izz="1.25e-07"/>
    </inertial>
  </link>
  <!-- Camera Joint -->
  <joint name="base_to_bottom_camera_link" type="fixed">
    <parent link="base_link"/>
    <child link="bottom_camera_link"/>
    <origin rpy="3.14149265359 0 0" xyz="0 0 0"/>
  </joint>
  <gazebo reference="bottom_camera_link">
    <material>Gazebo/White</material>
    <pose>0 0 0 3.14149265359 0 0</pose>
    <sensor name="camera" type="bottomcamera">
      <update_rate>30.0</update_rate>
      <visualize>true</visualize>
      <camera name="bottom_camera">
        <horizontal_fov>1.39626</horizontal_fov>
        <image>
          <width>640</width>
          <height>480</height>
          <format>R8G8B8</format>
        </image>
        <clip>
          <near>0.1</near>
          <far>500</far>
        </clip>
        <noise>
          <type>gaussian</type>
          <mean>0.0</mean>
          <stddev>0.07</stddev>
        </noise>
      </camera>
      <plugin filename="libgazebo_ros_camera.so" name="bottom_camera_controller">
        <always_on>1</always_on>
        <visualize>true</visualize>
        <update_rate>30.0</update_rate>
        <imageTopicName>bottom_camera_image_raw</imageTopicName>
        <frameName>bottom_camera_link</frameName>
        <hackBaseline>0.07</hackBaseline>
        <distortionK1>0.0</distortionK1>
        <distortionK2>0.0</distortionK2>
        <distortionK3>0.0</distortionK3>
        <distortionT1>0.0</distortionT1>
        <distortionT2>0.0</distortionT2>
      </plugin>
    </sensor>
  </gazebo>
  <!-- Front Arm -->
  <link name="front_arm">
    <visual>
      <geometry>
        <box size="0.2 0.04 0.02"/>
      </geometry>
      <origin rpy="0 0 0" xyz="0.1 0 0"/>
      <material name="white">
        <color rgba="1 1 1 1"/>
      </material>
    </visual>
    <!-- Front Arm Collision -->
    <collision>
      <geometry>
        <box size="0.2 0.04 0.02"/>
      </geometry>
      <origin rpy="0 0 0" xyz="0.1 0 0"/>
    </collision>
    <inertial>
      <mass value="0.01"/>
      <inertia ixx="3.46666666667e-05" ixy="0" ixz="0" iyy="1.66666666667e-06" iyz="0" izz="0.000134666666667"/>
    </inertial>
  </link>
  <gazebo reference="front_arm">
    <material>Gazebo/White</material>
  </gazebo>
  <!-- Front Motor Link -->
  <link name="front_motor">
    <visual>
      <geometry>
        <cylinder length="0.02" radius="0.02"/>
      </geometry>
      <origin rpy="0 0 0" xyz="0 0 0"/>
      <material name="magenta">
        <color rgba="1 0 1 1"/>
      </material>
    </visual>
    <!-- Front Motor Collision -->
    <collision>
      <geometry>
        <cylinder length="0.02" radius="0.02"/>
        <origin rpy="0 0 0" xyz="0 0 0"/>
      </geometry>
    </collision>
    <inertial>
      <mass value="0.08"/>
      <inertia ixx="1.06666666667e-05" ixy="0" ixz="0" iyy="1.06666666667e-05" iyz="0" izz="1.6e-05"/>
    </inertial>
  </link>
  <gazebo reference="front_motor">
    <material>Gazebo/DarkMagentaTransparent</material>
  </gazebo>
  <!-- Front Rotor Link -->
  <link name="front_rotor">
    <visual>
      <geometry>
        <cylinder length="0.0002" radius="0.1"/>
      </geometry>
      <origin rpy="0 0 0" xyz="0.0 0 0"/>
      <material name="black">
        <color rgba="0 0 0 0.5"/>
      </material>
    </visual>
    <!-- Front Rotor Collision -->
    <collision>
      <geometry>
        <cylinder length="0.0002" radius="0.1"/>
        <origin rpy="0 0 0" xyz="0.0 0 0"/>
      </geometry>
    </collision>
    <inertial>
      <mass value="0.001"/>
      <inertia ixx="5e-07" ixy="0" ixz="0" iyy="5e-07" iyz="0" izz="1e-06"/>
    </inertial>
  </link>
  <gazebo reference="front_rotor">
    <material>Gazebo/Black</material>
  </gazebo>
  <!---                           Front Joints                         -->
  <!-- Base to the front arm -->
  <joint name="base_to_front_arm" type="fixed">
    <parent link="base_link"/>
    <child link="front_arm"/>
    <origin rpy="0 0 0" xyz="0.025 0.0 0.025"/>
    <!-- <origin xyz="0.025 0 0.02" rpy="0 0 0"/> -->
  </joint>
  <!-- Front Motor Joint -->
  <joint name="front_arm_to_front_motor" type="fixed">
    <parent link="front_arm"/>
    <child link="front_motor"/>
    <origin rpy="0 0 0" xyz="0.18 0 0.02"/>
  </joint>
  <!-- Front Motor to Front Rotor -->
  <joint name="front_motor_to_front_rotor" type="continuous">
    <parent link="front_motor"/>
    <child link="front_rotor"/>
    <origin rpy="0 0 0" xyz="0 0 0.01"/>
    <axis xyz="0 0 1"/>
  </joint>
  <!-- Rear Arm -->
  <link name="rear_arm">
    <visual>
      <geometry>
        <box size="0.2 0.04 0.02"/>
      </geometry>
      <origin rpy="0 0 0" xyz="0.1 0 0"/>
      <material name="white">
        <color rgba="1 1 1 1"/>
      </material>
    </visual>
    <!-- Rear Arm Collision -->
    <collision>
      <geometry>
        <box size="0.2 0.04 0.02"/>
      </geometry>
      <origin rpy="0 0 0" xyz="0.1 0 0"/>
    </collision>
    <inertial>
      <mass value="0.01"/>
      <inertia ixx="3.46666666667e-05" ixy="0" ixz="0" iyy="1.66666666667e-06" iyz="0" izz="0.000134666666667"/>
    </inertial>
  </link>
  <gazebo reference="rear_arm">
    <material>Gazebo/White</material>
  </gazebo>
  <!-- Rear Motor Link -->
  <link name="rear_motor">
    <visual>
      <geometry>
        <cylinder length="0.02" radius="0.02"/>
      </geometry>
      <origin rpy="0 0 0" xyz="0 0 0"/>
      <material name="magenta">
        <color rgba="1 0 1 1"/>
      </material>
    </visual>
    <!-- Rear Motor Collision -->
    <collision>
      <geometry>
        <cylinder length="0.02" radius="0.02"/>
        <origin rpy="0 0 0" xyz="0 0 0"/>
      </geometry>
    </collision>
    <inertial>
      <mass value="0.08"/>
      <inertia ixx="1.06666666667e-05" ixy="0" ixz="0" iyy="1.06666666667e-05" iyz="0" izz="1.6e-05"/>
    </inertial>
  </link>
  <gazebo reference="rear_motor">
    <material>Gazebo/DarkMagentaTransparent</material>
  </gazebo>
  <!-- Rear Rotor Link -->
  <link name="rear_rotor">
    <visual>
      <geometry>
        <cylinder length="0.0002" radius="0.1"/>
      </geometry>
      <origin rpy="0 0 0" xyz="0.0 0 0"/>
      <material name="black">
        <color rgba="0 0 0 0.5"/>
      </material>
    </visual>
    <!-- Rear Rotor Collision -->
    <collision>
      <geometry>
        <cylinder length="0.0002" radius="0.1"/>
        <origin rpy="0 0 0" xyz="0.0 0 0"/>
      </geometry>
    </collision>
    <inertial>
      <mass value="0.001"/>
      <inertia ixx="5e-07" ixy="0" ixz="0" iyy="5e-07" iyz="0" izz="1e-06"/>
    </inertial>
  </link>
  <gazebo reference="rear_rotor">
    <material>Gazebo/Black</material>
  </gazebo>
  <!---                           Rear Joints                         -->
  <!-- Base to the Rear arm -->
  <joint name="base_to_rear_arm" type="fixed">
    <parent link="base_link"/>
    <child link="rear_arm"/>
    <origin rpy="0 0 3.14149265359" xyz="-0.025 0.0 0.025"/>
    <!-- <origin xyz="0.025 0 0.02" rpy="0 0 0"/> -->
  </joint>
  <!-- Rear Motor Joint -->
  <joint name="rear_arm_to_rear_motor" type="fixed">
    <parent link="rear_arm"/>
    <child link="rear_motor"/>
    <origin rpy="0 0 0" xyz="0.18 0 0.02"/>
  </joint>
  <!-- Rear Motor to Rear Rotor -->
  <joint name="rear_motor_to_rear_rotor" type="continuous">
    <parent link="rear_motor"/>
    <child link="rear_rotor"/>
    <origin rpy="0 0 0" xyz="0 0 0.01"/>
    <axis xyz="0 0 1"/>
  </joint>
  <!-- Right Arm -->
  <link name="right_arm">
    <visual>
      <geometry>
        <box size="0.2 0.04 0.02"/>
      </geometry>
      <origin rpy="0 0 0" xyz="0.1 0 0"/>
      <material name="red">
        <color rgba="1 0 0 1"/>
      </material>
    </visual>
    <!-- Right Arm Collision -->
    <collision>
      <geometry>
        <box size="0.2 0.04 0.02"/>
      </geometry>
      <origin rpy="0 0 0" xyz="0.1 0 0"/>
    </collision>
    <inertial>
      <mass value="0.01"/>
      <inertia ixx="3.46666666667e-05" ixy="0" ixz="0" iyy="1.66666666667e-06" iyz="0" izz="0.000134666666667"/>
    </inertial>
  </link>
  <gazebo reference="right_arm">
    <material>Gazebo/Red</material>
  </gazebo>
  <!-- Right Motor Link -->
  <link name="right_motor">
    <visual>
      <geometry>
        <cylinder length="0.02" radius="0.02"/>
      </geometry>
      <origin rpy="0 0 0" xyz="0 0 0"/>
      <material name="magenta">
        <color rgba="1 0 1 1"/>
      </material>
    </visual>
    <!-- Right Motor Collision -->
    <collision>
      <geometry>
        <cylinder length="0.02" radius="0.02"/>
        <origin rpy="0 0 0" xyz="0 0 0"/>
      </geometry>
    </collision>
    <inertial>
      <mass value="0.08"/>
      <inertia ixx="1.06666666667e-05" ixy="0" ixz="0" iyy="1.06666666667e-05" iyz="0" izz="1.6e-05"/>
    </inertial>
  </link>
  <gazebo reference="right_motor">
    <material>Gazebo/DarkMagentaTransparent</material>
  </gazebo>
  <!-- Right Rotor Link -->
  <link name="right_rotor">
    <visual>
      <geometry>
        <cylinder length="0.0002" radius="0.1"/>
      </geometry>
      <origin rpy="0 0 0" xyz="0.0 0 0"/>
      <material name="black">
        <color rgba="0 0 0 0.5"/>
      </material>
    </visual>
    <!-- Right Rotor Collision -->
    <collision>
      <geometry>
        <cylinder length="0.0002" radius="0.1"/>
        <origin rpy="0 0 0" xyz="0.0 0 0"/>
      </geometry>
    </collision>
    <inertial>
      <mass value="0.001"/>
      <inertia ixx="5e-07" ixy="0" ixz="0" iyy="5e-07" iyz="0" izz="1e-06"/>
    </inertial>
  </link>
  <gazebo reference="right_rotor">
    <material>Gazebo/Black</material>
  </gazebo>
  <!---                           Right Joints                         -->
  <!-- Base to the Right arm -->
  <joint name="base_to_right_arm" type="fixed">
    <parent link="base_link"/>
    <child link="right_arm"/>
    <origin rpy="0 0 -1.57074632679" xyz="0.0 -0.025 0.025"/>
    <!-- <origin xyz="0.025 0 0.02" rpy="0 0 0"/> -->
  </joint>
  <!-- Right Motor Joint -->
  <joint name="right_arm_to_right_motor" type="fixed">
    <parent link="right_arm"/>
    <child link="right_motor"/>
    <origin rpy="0 0 -1.57074632679" xyz="0.18 0 0.02"/>
  </joint>
  <!-- Right Motor to Right Rotor -->
  <joint name="right_motor_to_right_rotor" type="continuous">
    <parent link="right_motor"/>
    <child link="right_rotor"/>
    <origin rpy="0 0 0" xyz="0 0 0.01"/>
    <axis xyz="0 0 1"/>
  </joint>
  <!-- Left Arm -->
  <link name="left_arm">
    <visual>
      <geometry>
        <box size="0.2 0.04 0.02"/>
      </geometry>
      <origin rpy="0 0 0" xyz="0.1 0 0"/>
      <material name="red">
        <color rgba="1 0 0 1"/>
      </material>
    </visual>
    <!-- Left Arm Collision -->
    <collision>
      <geometry>
        <box size="0.2 0.04 0.02"/>
      </geometry>
      <origin rpy="0 0 0" xyz="0.1 0 0"/>
    </collision>
    <inertial>
      <mass value="0.01"/>
      <inertia ixx="3.46666666667e-05" ixy="0" ixz="0" iyy="1.66666666667e-06" iyz="0" izz="0.000134666666667"/>
    </inertial>
  </link>
  <gazebo reference="left_arm">
    <material>Gazebo/Red</material>
  </gazebo>
  <!-- Left Motor Link -->
  <link name="left_motor">
    <visual>
      <geometry>
        <cylinder length="0.02" radius="0.02"/>
      </geometry>
      <origin rpy="0 0 0" xyz="0 0 0"/>
      <material name="magenta">
        <color rgba="1 0 1 1"/>
      </material>
    </visual>
    <!-- Left Motor Collision -->
    <collision>
      <geometry>
        <cylinder length="0.02" radius="0.02"/>
        <origin rpy="0 0 0" xyz="0 0 0"/>
      </geometry>
    </collision>
    <inertial>
      <mass value="0.08"/>
      <inertia ixx="1.06666666667e-05" ixy="0" ixz="0" iyy="1.06666666667e-05" iyz="0" izz="1.6e-05"/>
    </inertial>
  </link>
  <gazebo reference="left_motor">
    <material>Gazebo/DarkMagentaTransparent</material>
  </gazebo>
  <!-- Leftt Rotor Link -->
  <link name="left_rotor">
    <visual>
      <geometry>
        <cylinder length="0.0002" radius="0.1"/>
      </geometry>
      <origin rpy="0 0 0" xyz="0.0 0 0"/>
      <material name="black">
        <color rgba="0 0 0 0.5"/>
      </material>
    </visual>
    <!-- Left Rotor Collision -->
    <collision>
      <geometry>
        <cylinder length="0.0002" radius="0.1"/>
        <origin rpy="0 0 0" xyz="0.0 0 0"/>
      </geometry>
    </collision>
    <inertial>
      <mass value="0.001"/>
      <inertia ixx="5e-07" ixy="0" ixz="0" iyy="5e-07" iyz="0" izz="1e-06"/>
    </inertial>
  </link>
  <gazebo reference="left_rotor">
    <material>Gazebo/Black</material>
  </gazebo>
  <!---                           Left Joints                         -->
  <!-- Base to the Left arm -->
  <joint name="base_to_left_arm" type="fixed">
    <parent link="base_link"/>
    <child link="left_arm"/>
    <origin rpy="0 0 1.57074632679" xyz="0.0 0.025 0.025"/>
    <!-- <origin xyz="0.025 0 0.02" rpy="0 0 0"/> -->
  </joint>
  <!-- Right Motor Joint -->
  <joint name="left_arm_to_left_motor" type="fixed">
    <parent link="left_arm"/>
    <child link="left_motor"/>
    <origin rpy="0 0 1.57074632679" xyz="0.18 0 0.02"/>
  </joint>
  <!-- Left Motor to Left Rotor -->
  <joint name="left_motor_to_left_rotor" type="continuous">
    <parent link="left_motor"/>
    <child link="left_rotor"/>
    <origin rpy="0 0 0" xyz="0 0 0.01"/>
    <axis xyz="0 0 1"/>
  </joint>
  <!-- Quadrotor Drive Plugin -->
  <gazebo>
    <plugin filename="libgeneric_quad_sim.so" name="quadrotor_drive_controller">
      <rosDebugLevel>Debug</rosDebugLevel>
      <publish_tf_>true</publish_tf_>
      <publishRotorTF>true</publishRotorTF>
      <publishRotorJointState>true</publishRotorJointState>
      <commandTopic>cmd_vel</commandTopic>
      <robotBaseFrame>base_link</robotBaseFrame>
      <imu_data>imu_data</imu_data>
      <forceTopic>cmd_force</forceTopic>
      <updateRate>1000.0</updateRate>
      <cameraMass>camera_mass</cameraMass>
      <baseMass>base_m</baseMass>
      <baseLength>l_base</baseLength>
      <armMass>arm_m</armMass>
      <armLength>l_arm</armLength>
      <motorMass>motor_m</motorMass>
      <motorRadius>motor_radius</motorRadius>
      <rotorMass>rotor_m</rotorMass>
      <rotorRadius>rotor_radius</rotorRadius>
      <rotorTorque>0.0</rotorTorque>
      <rotorAccel>0.0</rotorAccel>
      <frontJoint>ront_motor_to_front_rotor</frontJoint>
      <rearJoint>rear_motor_to_rear_rotor</rearJoint>
      <leftJoint>left_motor_to_left_rotor</leftJoint>
      <rightJoint>right_motor_to_right_rotor</rightJoint>
    </plugin>
  </gazebo>
</robot>

